2025-01-19 11:48:19,641 - ERROR - Exception on /api/hour/memari [GET]
Traceback (most recent call last):
  File "/home/robin/Documents/Projects/weather_api/vir_env/lib/python3.12/site-packages/flask/app.py", line 1511, in wsgi_app
    response = self.full_dispatch_request()
               ^^^^^^^^^^^^^^^^^^^^^^^^^^^^
  File "/home/robin/Documents/Projects/weather_api/vir_env/lib/python3.12/site-packages/flask/app.py", line 919, in full_dispatch_request
    rv = self.handle_user_exception(e)
         ^^^^^^^^^^^^^^^^^^^^^^^^^^^^^
  File "/home/robin/Documents/Projects/weather_api/vir_env/lib/python3.12/site-packages/flask/app.py", line 917, in full_dispatch_request
    rv = self.dispatch_request()
         ^^^^^^^^^^^^^^^^^^^^^^^
  File "/home/robin/Documents/Projects/weather_api/vir_env/lib/python3.12/site-packages/flask/app.py", line 902, in dispatch_request
    return self.ensure_sync(self.view_functions[rule.endpoint])(**view_args)  # type: ignore[no-any-return]
           ^^^^^^^^^^^^^^^^^^^^^^^^^^^^^^^^^^^^^^^^^^^^^^^^^^^^^^^^^^^^^^^^^
  File "/home/robin/Documents/Projects/weather_api/app/api/call.py", line 32, in hour_weather
    ls.append(item.hour)
              ^^^^^^^^^
AttributeError: 'dict' object has no attribute 'hour'
2025-01-19 11:49:46,223 - ERROR - Exception on /api/hour/memari [GET]
Traceback (most recent call last):
  File "/home/robin/Documents/Projects/weather_api/vir_env/lib/python3.12/site-packages/flask/app.py", line 1511, in wsgi_app
    response = self.full_dispatch_request()
               ^^^^^^^^^^^^^^^^^^^^^^^^^^^^
  File "/home/robin/Documents/Projects/weather_api/vir_env/lib/python3.12/site-packages/flask/app.py", line 919, in full_dispatch_request
    rv = self.handle_user_exception(e)
         ^^^^^^^^^^^^^^^^^^^^^^^^^^^^^
  File "/home/robin/Documents/Projects/weather_api/vir_env/lib/python3.12/site-packages/flask/app.py", line 917, in full_dispatch_request
    rv = self.dispatch_request()
         ^^^^^^^^^^^^^^^^^^^^^^^
  File "/home/robin/Documents/Projects/weather_api/vir_env/lib/python3.12/site-packages/flask/app.py", line 902, in dispatch_request
    return self.ensure_sync(self.view_functions[rule.endpoint])(**view_args)  # type: ignore[no-any-return]
           ^^^^^^^^^^^^^^^^^^^^^^^^^^^^^^^^^^^^^^^^^^^^^^^^^^^^^^^^^^^^^^^^^
  File "/home/robin/Documents/Projects/weather_api/app/api/call.py", line 32, in hour_weather
    ls.append(item.hour)
              ^^^^^^^^^
AttributeError: 'dict' object has no attribute 'hour'
2025-01-19 11:50:37,103 - ERROR - Exception on /api/hour/memari [GET]
Traceback (most recent call last):
  File "/home/robin/Documents/Projects/weather_api/vir_env/lib/python3.12/site-packages/flask/app.py", line 1511, in wsgi_app
    response = self.full_dispatch_request()
               ^^^^^^^^^^^^^^^^^^^^^^^^^^^^
  File "/home/robin/Documents/Projects/weather_api/vir_env/lib/python3.12/site-packages/flask/app.py", line 919, in full_dispatch_request
    rv = self.handle_user_exception(e)
         ^^^^^^^^^^^^^^^^^^^^^^^^^^^^^
  File "/home/robin/Documents/Projects/weather_api/vir_env/lib/python3.12/site-packages/flask/app.py", line 917, in full_dispatch_request
    rv = self.dispatch_request()
         ^^^^^^^^^^^^^^^^^^^^^^^
  File "/home/robin/Documents/Projects/weather_api/vir_env/lib/python3.12/site-packages/flask/app.py", line 902, in dispatch_request
    return self.ensure_sync(self.view_functions[rule.endpoint])(**view_args)  # type: ignore[no-any-return]
           ^^^^^^^^^^^^^^^^^^^^^^^^^^^^^^^^^^^^^^^^^^^^^^^^^^^^^^^^^^^^^^^^^
  File "/home/robin/Documents/Projects/weather_api/app/api/call.py", line 32, in hour_weather
    ls.append(item.hour)
              ^^^^^^^^^
AttributeError: 'dict' object has no attribute 'hour'
2025-01-19 15:32:41,321 - ERROR - Exception on /api/hour/memari [GET]
Traceback (most recent call last):
  File "/home/robin/Documents/Projects/weather_api/vir_env/lib/python3.12/site-packages/flask/app.py", line 1511, in wsgi_app
    response = self.full_dispatch_request()
               ^^^^^^^^^^^^^^^^^^^^^^^^^^^^
  File "/home/robin/Documents/Projects/weather_api/vir_env/lib/python3.12/site-packages/flask/app.py", line 919, in full_dispatch_request
    rv = self.handle_user_exception(e)
         ^^^^^^^^^^^^^^^^^^^^^^^^^^^^^
  File "/home/robin/Documents/Projects/weather_api/vir_env/lib/python3.12/site-packages/flask/app.py", line 917, in full_dispatch_request
    rv = self.dispatch_request()
         ^^^^^^^^^^^^^^^^^^^^^^^
  File "/home/robin/Documents/Projects/weather_api/vir_env/lib/python3.12/site-packages/flask/app.py", line 902, in dispatch_request
    return self.ensure_sync(self.view_functions[rule.endpoint])(**view_args)  # type: ignore[no-any-return]
           ^^^^^^^^^^^^^^^^^^^^^^^^^^^^^^^^^^^^^^^^^^^^^^^^^^^^^^^^^^^^^^^^^
  File "/home/robin/Documents/Projects/weather_api/app/api/call.py", line 31, in hour_weather
    if item['datetime'].hour == int(hour):
                                ^^^^^^^^^
TypeError: int() argument must be a string, a bytes-like object or a real number, not 'NoneType'
